File: Rb2YbNaF6/26Aug2020Exp/partial low temp/Rb2YbNaF6_2p4mg_pk3029_HC_26Aug20.raw
[Header]
TITLE,
BYAPP,HeatCapacity,3.9.6,4.0
INFO,PPMS Heat Capacity Option 3.9.6 Build 3,APPNAME
DATATYPE,TIME,1
DATATYPE,COMMENT,2
STARTUPAXIS, X, 1, LINEAR, AUTO
STARTUPAXIS, Y1, 4, LINEAR, AUTO
[Data]
Time Stamp (Seconds),Comment (),Therm Res (Ohms),Platform Temp (Kelvin),Heater Power (Watts),Platform Temp Fit (Kelvin),Sample Temp Fit (Kelvin)
3807626285.6241,Error: Temperature of platform does not match the system temperature : System = 1.0004 K;  Platform = 1.0219 K
3807626332.79538,CALFILE: C:\QDDYNA~1\HEATCA~1\TempCal\DR\DRPuck3029_smoothedv4.cal|Addenda #57 measured on 8/25/2020 from 0.067939 to 1.0332 K
3807626332.80633,BEGIN:PULSE:PARAMS
3807626332.80633,ThResSigmaPerCycle=0.504740030770174
3807626332.80633,TempSigmaPerCycle=0.000368826734869598
3807626332.80633,NBinsOn=128
3807626332.80633,NBinsOff=128
3807626332.80633,Period=6.08519490926886
3807626332.80633,Iterations=1
3807626332.80633,HtrOverLoad=0
3807626332.80633,NCycRec=6
3807626332.80633,ThFreqHz=245.017959594727
3807626332.80633,NSampPerBin=6
3807626332.80633,PPMSTemp=1.00015795230865
3807626332.80633,EstTau=3.04259745463443
3807626332.80633,ThermOverload=0
3807626332.80633,ThResCorrFact=1
3807626332.80633,AvgHtrOnResistance=1698.09949049247
3807626332.80633,IsAddenda=0
3807626332.80633,AddendafromTbl=3.63036767481374E-7
3807626332.80633,AddendafromTblMinMidMax=3.62513499952078E-7|3.62959001036095E-7|3.63369435428627E-7
3807626332.80633,AddendaOffsetMinMidMax=0|0|0
3807626332.80633,AddendaErrfromTbl=3.51836024249513E-9
3807626332.80633,CondfromTbl=1.68700454084742E-7
3807626332.80633,TempMinMidMax=1.02247189785756|1.03389078585052|1.04530967384349
3807626332.80633,CondfromTblMinMidMax=1.67524896981442E-7|1.70257629726109E-7|1.72987532618652E-7
3807626332.80633,DisableTau2Fitting=0
3807626332.80633,HtrCurrOn=1.75179877054461E-6
3807626332.80633,StableStartTemperature=1.02200506607724
3807626332.80633,TimeStamp=3807626332.80633
3807626332.80633,PPMSStatus=833
3807626332.80633,PuckTemp=1.00017
3807626332.80633,SystemTemp=1.00017
3807626332.80633,Field=-0.03600527
3807626332.80633,Pressure=9.8999999E-6
3807626332.80633,SampleTemp=1.0338581
3807626332.80633,TempRise=0.021989547
3807626332.80633,SampHC=0.069118266
3807626332.80633,SampHCErr=0.005826
3807626332.80633,AddendaHC=0.36303677
3807626332.80633,AddendaHCErr=0.003518
3807626332.80633,TotalHC=0.43215503
3807626332.80633,TotalHCErr=0.004644
3807626332.80633,FitDeviation=2.0701882
3807626332.80633,TimeConsttau1=2.6549591
3807626332.80633,TimeConsttau2=
3807626332.80633,SampleCoupling=
3807626332.80633,DebyeTemp=
3807626332.80633,DebyeTempErr=
3807626332.80633,CalCorrection=1
3807626332.80633,ThermCondWire=1.6277277E-7
3807626332.80633,AddendaOffset=0
3807626332.80633,END:PULSE:PARAMS
3807626332.83082,,4087.587890625,1.02247189785756,5.23119200281327E-9,1.0230104630432,1.0230104630432
3807626332.85531,,4087.201171875,1.02275463340175,5.23066952259579E-9,1.02330302792468,1.02330302792468
3807626332.87979,,4086.29345703125,1.02341878853128,5.23023065552786E-9,1.02359290674204,1.02359290674204
3807626332.90428,,4086.15869140625,1.02351745487024,5.22986275766981E-9,1.02388012415627,1.02388012415627
3807626332.92877,,4085.53002929687,1.02397792858539,5.22933375154797E-9,1.02416470460194,1.02416470460194
3807626332.95326,,4085.1005859375,1.02429267985688,5.2287766024636E-9,1.0244466722893,1.0244466722893
3807626332.97775,,4084.7607421875,1.02454187535981,5.22866729356564E-9,1.02472605120631,1.02472605120631
3807626333.00223,,4084.353515625,1.02484061346825,5.22799430967895E-9,1.02500286512071,1.02500286512071
3807626333.02672,,4083.65551757812,1.02535299714203,5.2274008602516E-9,1.02527713758201,1.02527713758201
3807626333.05121,,4083.64282226562,1.02536232042254,5.22720345164484E-9,1.02554889192352,1.02554889192352
3807626333.0757,,4083.4677734375,1.02549088853593,5.22650273266464E-9,1.02581815126432,1.02581815126432
3807626333.10019,,4082.58520507812,1.02613951825809,5.22617072728054E-9,1.02608493851122,1.02608493851122
3807626333.12467,,4082.451171875,1.02623808370936,5.2258636019068E-9,1.02634927636076,1.02634927636076
3807626333.14916,,4081.94799804687,1.02660824909137,5.22518449998478E-9,1.02661118730105,1.02661118730105
3807626333.17365,,4081.94995117188,1.0266068118226,5.22497159235518E-9,1.02687069361377,1.02687069361377
3807626333.19814,,4081.1845703125,1.02717029871911,5.22446705837467E-9,1.02712781737601,1.02712781737601
3807626333.22263,,4080.56201171875,1.02762901810902,5.22425619009018E-9,1.02738258046219,1.02738258046219
3807626333.24711,,4080.54931640625,1.02763837594398,5.22370597477918E-9,1.02763500454588,1.02763500454588
3807626333.2716,,4080.01391601562,1.02803315416253,5.22346166123486E-9,1.02788511110168,1.02788511110168
3807626333.29609,,4080.06103515625,1.02799840063912,5.22295712725436E-9,1.028132921407,1.028132921407
3807626333.32058,,4079.47119140625,1.02843359135892,5.22247053951084E-9,1.02837845654393,1.02837845654393
3807626333.34507,,4079.13354492188,1.02868284767785,5.22213934986478E-9,1.02862173740099,1.02862173740099
3807626333.36955,,4078.82299804687,1.0289121876703,5.22175840019801E-9,1.02886278467492,1.02886278467492
3807626333.39404,,4078.46118164063,1.02917949810876,5.22145127482427E-9,1.02910161887245,1.02910161887245
3807626333.41853,,4078.490234375,1.0291580296289,5.22113843928422E-9,1.02933826031204,1.02933826031204
3807626333.44302,,4077.56884765625,1.02983925162444,5.22074647715385E-9,1.02957272912558,1.02957272912558
3807626333.46751,,4077.78588867188,1.02967871579589,5.22035900158273E-9,1.02980504526014,1.02980504526014
3807626333.49199,,4077.24243164063,1.0300807661357,5.22000578700947E-9,1.03003522847968,1.03003522847968
3807626333.51648,,4076.90576171875,1.03032996663037,5.2195257251703E-9,1.03026329836665,1.03026329836665
3807626333.54097,,4076.34326171875,1.03074654961588,5.21954285566924E-9,1.03048927432377,1.03048927432377
3807626333.56546,,4076.572265625,1.03057691720269,5.21866308218828E-9,1.03071317557558,1.03071317557558
3807626333.58995,,4075.96630859375,1.03102587560082,5.21885110980753E-9,1.03093502117015,1.03093502117015
3807626333.61443,,4075.3984375,1.03144691257899,5.21869000154375E-9,1.03115482998063,1.03115482998063
3807626333.63892,,4075.50268554687,1.03136959836132,5.21813733901862E-9,1.03137262070693,1.03137262070693
3807626333.66341,,4075.064453125,1.03169467302485,5.2177315093415E-9,1.03158841187725,1.03158841187725
3807626333.6879,,4074.6962890625,1.03196790436461,5.21736932164975E-9,1.0318022218497,1.0318022218497
3807626333.71239,,4074.71142578125,1.03195666833032,5.21705159168143E-9,1.03201406881384,1.03201406881384
3807626333.73687,,4074.46850585937,1.03213701324632,5.21661027739937E-9,1.0322239707922,1.0322239707922
3807626333.76136,,4074.06958007812,1.03243329199695,5.2165282957259E-9,1.03243194564189,1.03243194564189
3807626333.78585,,4073.58056640625,1.03279667229203,5.21622606478043E-9,1.03263801105603,1.03263801105603
3807626333.81034,,4073.57006835937,1.03280447561116,5.21594096433389E-9,1.03284218456533,1.03284218456533
3807626333.83483,,4073.34985351562,1.03296818657858,5.21559182845085E-9,1.03304448353954,1.03304448353954
3807626333.85931,,4073.24951171875,1.03304279654455,5.21555634384592E-9,1.03324492518891,1.03324492518891
3807626333.8838,,4073.0068359375,1.03322327737237,5.21502856133115E-9,1.03344352656573,1.03344352656573
3807626333.90829,,4072.20874023438,1.03381720259097,5.21485929568692E-9,1.0336403045657,1.0336403045657
3807626333.93278,,4072.33862304687,1.03372050776759,5.21409454127023E-9,1.03383527592939,1.03383527592939
3807626333.95727,,4072.02075195313,1.0339571824243,5.21404233403539E-9,1.03402845724371,1.03402845724371
3807626333.98175,,4071.56762695313,1.03429471871759,5.21404478124952E-9,1.03421986494324,1.03421986494324
3807626334.00624,,4071.740234375,1.03416612038962,5.21358144204026E-9,1.03440951531171,1.03440951531171
3807626334.03073,,4070.955078125,1.03475130419692,5.21358144204026E-9,1.03459742448332,1.03459742448332
3807626334.05522,,4070.79174804687,1.034873105147,5.2127934390893E-9,1.03478360844416,1.03478360844416
3807626334.07971,,4070.86303710937,1.03481993945073,5.21285502731166E-9,1.03496808303355,1.03496808303355
3807626334.10419,,4070.3125,1.03523063569586,5.21260010917277E-9,1.03515086394537,1.03515086394537
3807626334.12868,,4070.005859375,1.03545950542911,5.21223792148102E-9,1.03533196672943,1.03533196672943
3807626334.15317,,4069.99389648438,1.03546843598148,5.21176316193914E-9,1.03551140679276,1.03551140679276
3807626334.17766,,4069.44409179687,1.03587901600341,5.21169953437167E-9,1.03568919940096,1.03568919940096
3807626334.20215,,4069.72924804687,1.03566603462828,5.21163142024496E-9,1.03586535967945,1.03586535967945
3807626334.22663,,4069.5576171875,1.03579421583329,5.21105877213774E-9,1.03603990261481,1.03603990261481
3807626334.25112,,4068.79858398438,1.03636141259262,5.21089073010058E-9,1.03621284305599,1.03621284305599
3807626334.27561,,4068.56689453125,1.03653464893869,5.21063254900951E-9,1.03638419571565,1.03638419571565
3807626334.3001,,4068.38452148438,1.03667104505907,5.21047144074572E-9,1.03655397517134,1.03655397517134
3807626334.32459,,4068.43017578125,1.03663689756198,5.20994896052824E-9,1.03672219586678,1.03672219586678
3807626334.34907,,4068.451171875,1.03662119399668,5.20986126868846E-9,1.03688887211311,1.03688887211311
3807626334.37356,,4067.76904296875,1.03713158108436,5.20956882659952E-9,1.03705401809003,1.03705401809003
3807626334.39805,,4067.57983398438,1.03727322686273,5.20941098128792E-9,1.0372176478471,1.0372176478471
3807626334.42254,,4067.39672851562,1.03741033427561,5.20917156217186E-9,1.03737977530485,1.03737977530485
3807626334.44703,,4067.35180664063,1.03744397593113,5.20889176402261E-9,1.03754041425603,1.03754041425603
3807626334.47151,,4067.08520507812,1.03764366944809,5.20852916846185E-9,1.03769957836675,1.03769957836675
3807626334.496,,4067.10107421875,1.03763178112732,5.20824121293215E-9,1.03785728117766,1.03785728117766
3807626334.52049,,4066.32275390625,1.0382151264958,5.20802789743352E-9,1.03801353610507,1.03801353610507
3807626334.54498,,4066.51318359375,1.03807235008533,5.20774646780818E-9,1.03816835644214,1.03816835644214
3807626334.56947,,4066.32592773438,1.03821274661902,5.20762614644662E-9,1.03832175535996,1.03832175535996
3807626334.59395,,4066.09765625,1.03838393796811,5.20749889131168E-9,1.03847374590871,1.03847374590871
3807626334.61844,,4065.73583984375,1.03865537774532,5.20702821046002E-9,1.03862434101875,1.03862434101875
3807626334.64293,,4065.39135742188,1.03891392382626,5.20678308117766E-9,1.03877355350174,1.03877355350174
3807626334.66742,,4065.29077148438,1.03898943742626,5.20666031260197E-9,1.03892139605168,1.03892139605168
3807626334.69191,,4065.7607421875,1.03863669184567,5.20639723708263E-9,1.03906788124606,1.03906788124606
3807626334.71639,,4064.9072265625,1.03927746327307,5.20640661807014E-9,1.03921302154687,1.03921302154687
3807626334.74088,,4064.83154296875,1.03933431422616,5.20601180085662E-9,1.03935682930171,1.03935682930171
3807626334.76537,,4064.52685546875,1.03956323789627,5.2057307791003E-9,1.0394993167448,1.0394993167448
3807626334.78986,,4064.36645507812,1.03968378696148,5.20551134556633E-9,1.03964049599804,1.03964049599804
3807626334.81435,,4063.93408203125,1.04000885407308,5.20542569307166E-9,1.03978037907204,1.03978037907204
3807626334.83883,,4063.87573242188,1.04005273557763,5.20538001174117E-9,1.03991897786712,1.03991897786712
3807626334.86332,,4063.83227539063,1.04008541921874,5.20522910020295E-9,1.04005630417437,1.04005630417437
3807626334.88781,,4063.77416992188,1.04012912250745,5.20481307380027E-9,1.04019236967662,1.04019236967662
3807626334.9123,,4063.28540039063,1.04049686618607,5.20470254129524E-9,1.04032718594942,1.04032718594942
3807626334.93679,,4063.23608398438,1.04053398329901,5.20457324681519E-9,1.04046076446207,1.04046076446207
3807626334.96127,,4063.26586914063,1.04051156576609,5.20444109725199E-9,1.04059311657854,1.04059311657854
3807626334.98576,,4062.86840820313,1.04081077790824,5.20413927417554E-9,1.0407242535585,1.0407242535585
3807626335.01025,,4063.04736328125,1.04067604107386,5.20379503272077E-9,1.04085418655821,1.04085418655821
3807626335.03474,,4062.1552734375,1.04134799393785,5.20357233623463E-9,1.04098292663153,1.04098292663153
3807626335.05923,,4062.33178710937,1.04121498001754,5.20341000436378E-9,1.04111048473081,1.04111048473081
3807626335.08371,,4061.80151367188,1.04161465951478,5.20326765807502E-9,1.04123687170788,1.04123687170788
3807626335.1082,,4062.00390625,1.04146208113412,5.20308697209817E-9,1.04136209831489,1.04136209831489
3807626335.13269,,4061.92797851562,1.0415193166399,5.20298459697359E-9,1.04148617520532,1.04148617520532
3807626335.15718,,4061.78637695313,1.04162607219176,5.20284469789897E-9,1.04160911293482,1.04160911293482
3807626335.18167,,4061.36254882812,1.04194571230969,5.20230590292059E-9,1.04173092196212,1.04173092196212
3807626335.20615,,4061.44995117188,1.0418797822759,5.20225614289988E-9,1.04185161264993,1.04185161264993
3807626335.23064,,4061.11010742188,1.04213617522976,5.20201386870067E-9,1.04197119526584,1.04197119526584
3807626335.25513,,4061.1015625,1.04214262325515,5.20242989510335E-9,1.04208967998314,1.04208967998314
3807626335.27962,,4060.46020507812,1.04262678478291,5.20174956957427E-9,1.04220707688175,1.04220707688175
3807626335.30411,,4060.64013671875,1.04249091608074,5.20141144615483E-9,1.04232339594902,1.04232339594902
3807626335.32859,,4060.42065429687,1.04265665407196,5.20146977142501E-9,1.04243864708061,1.04243864708061
3807626335.35308,,4060.51586914063,1.0425847489586,5.20120017000132E-9,1.04255284008134,1.04255284008134
3807626335.37757,,4060.05981445313,1.04292923155259,5.20114877850452E-9,1.04266598466601,1.04266598466601
3807626335.40206,,4060.08032226562,1.04291373679942,5.20108555880607E-9,1.04277809046021,1.04277809046021
3807626335.42655,,4059.60766601562,1.04327095213726,5.20074743538664E-9,1.04288916700117,1.04288916700117
3807626335.45103,,4059.8759765625,1.04306814819897,5.20082411476282E-9,1.04299922373856,1.04299922373856
3807626335.47552,,4059.43237304687,1.0434034839931,5.20074906686273E-9,1.04310827003527,1.04310827003527
3807626335.50001,,4059.26049804687,1.04353345909741,5.20021557418164E-9,1.04321631516827,1.04321631516827
3807626335.5245,,4059.1044921875,1.04365145719085,5.20030204241436E-9,1.04332336832932,1.04332336832932
3807626335.54899,,4059.10986328125,1.04364739428568,5.19985909665621E-9,1.0434294386258,1.0434294386258
3807626335.57347,,4059.1806640625,1.04359384030083,5.19982279631323E-9,1.04353453508149,1.04353453508149
3807626335.59796,,4058.73779296875,1.04392890554539,5.19954136668789E-9,1.04363866663729,1.04363866663729
3807626335.62245,,4058.53369140625,1.0440833844967,5.19940146761326E-9,1.04374184215204,1.04374184215204
3807626335.64694,,4058.52026367188,1.04409354893187,5.1992811462517E-9,1.04384407040324,1.04384407040324
3807626335.67143,,4058.57641601562,1.04405104422103,5.19924770099188E-9,1.0439453600878,1.0439453600878
3807626335.69591,,4058.41967773438,1.04416969506898,5.19891569560778E-9,1.04404571982279,1.04404571982279
3807626335.7204,,4058.27294921875,1.04428078904111,5.19887490870556E-9,1.04414515814614,1.04414515814614
3807626335.74489,,4057.56005859375,1.04482082931578,5.19873949619018E-9,1.04424368351743,1.04424368351743
3807626335.76938,,4058.00024414063,1.04448731758134,5.19837730849843E-9,1.04434130431855,1.04434130431855
3807626335.79387,,4057.48168945313,1.04488022536367,5.19827452550483E-9,1.04443802885443,1.04443802885443
3807626335.81835,,4057.7607421875,1.04466875686765,5.19832836421577E-9,1.04453386535377,1.04453386535377
3807626335.84284,,4057.29931640625,1.04501846802538,5.19789153649295E-9,1.04462882196972,1.04462882196972
3807626335.86733,,4057.14331054687,1.04513674817173,5.19775897906073E-9,1.04472290678054,1.04472290678054
3807626335.89182,,4057.16723632812,1.04511860672169,5.19770881117099E-9,1.04481612779038,1.04481612779038
3807626335.91631,,4057.140625,1.04513878448992,5.19784300007931E-9,1.04490849292986,1.04490849292986
3807626335.94079,,4056.91528320313,1.04530967384349,5.19763457900895E-9,1.0450000100568,1.0450000100568
3807626335.96528,,4057.33129882812,1.04499422244652,0,1.04494350295055,1.04494350295055
3807626335.98977,,4058.26318359375,1.04428818368801,0,1.04474078245648,1.04474078245648
3807626336.01426,,4058.50708007812,1.04410352871959,0,1.04453992315725,1.04453992315725
3807626336.03875,,4058.3046875,1.04425675704868,0,1.04434090796507,1.04434090796507
3807626336.06323,,4058.92895507812,1.04378425490488,0,1.04414371994901,1.04414371994901
3807626336.08772,,4059.154296875,1.04361378400359,0,1.04394834233362,1.04394834233362
3807626336.11221,,4059.70361328125,1.04319842229174,0,1.04375475849744,1.04375475849744
3807626336.1367,,4059.67626953125,1.04321909151316,0,1.04356295197163,1.04356295197163
3807626336.16119,,4059.8798828125,1.04306519612762,0,1.04337290643855,1.04337290643855
3807626336.18567,,4060.22045898438,1.04280786632654,0,1.04318460573036,1.04318460573036
3807626336.21016,,4060.189453125,1.04283128907634,0,1.04299803382767,1.04299803382767
3807626336.23465,,4060.76000976562,1.04240041488446,0,1.04281317485817,1.04281317485817
3807626336.25914,,4061.05932617188,1.04217449591019,0,1.04263001309526,1.04263001309526
3807626336.28363,,4061.20849609375,1.04206193563777,0,1.04244853295674,1.04244853295674
3807626336.30811,,4061.28173828125,1.04200667619406,0,1.04226871900347,1.04226871900347
3807626336.3326,,4061.50537109375,1.0418379811032,0,1.04209055593806,1.04209055593806
3807626336.35709,,4062.10302734375,1.04138737005255,0,1.04191402860355,1.04191402860355
3807626336.38158,,4061.7880859375,1.04162478365277,0,1.04173912198215,1.04173912198215
3807626336.40607,,4062.1455078125,1.04135535376982,0,1.04156582119395,1.04156582119395
3807626336.43055,,4062.7216796875,1.04092127290753,0,1.04139411149567,1.04139411149567
3807626336.45504,,4062.65380859375,1.04097239039398,0,1.04122397827935,1.04122397827935
3807626336.47953,,4063.06689453125,1.04066133759753,0,1.04105540707118,1.04105540707118
3807626336.50402,,4063.0166015625,1.0406991997587,0,1.04088838353022,1.04088838353022
3807626336.52851,,4063.46728515625,1.04035999305072,0,1.04072289344721,1.04072289344721
3807626336.55299,,4063.6767578125,1.04020239669094,0,1.04055892274332,1.04055892274332
3807626336.57748,,4064.00854492188,1.03995285916845,0,1.04039645746902,1.04039645746902
3807626336.60197,,4064.03857421875,1.03993027904744,0,1.0402354838028,1.0402354838028
3807626336.62646,,4063.8525390625,1.04007017888136,0,1.04007598805009,1.04007598805009
3807626336.65095,,4064.11694335937,1.03987135430868,0,1.03991795664203,1.03991795664203
3807626336.67543,,4064.53173828125,1.03955956858217,0,1.03976137613434,1.03976137613434
3807626336.69992,,4064.482421875,1.03959662965914,0,1.03960623320619,1.03960623320619
3807626336.72441,,4064.96166992188,1.03923657048711,0,1.03945251465901,1.03945251465901
3807626336.7489,,4065.37329101562,1.03892748627038,0,1.03930020741545,1.03930020741545
3807626336.77339,,4065.21728515625,1.03904461215815,0,1.03914929851821,1.03914929851821
3807626336.79787,,4065.66015625,1.03871217168197,0,1.03899977512893,1.03899977512893
3807626336.82236,,4065.79931640625,1.03860774813231,0,1.03885162452715,1.03885162452715
3807626336.84685,,4065.943359375,1.0384996791252,0,1.03870483410918,1.03870483410918
3807626336.87134,,4066.07885742188,1.03839803818807,0,1.03855939138707,1.03855939138707
3807626336.89583,,4066.54272460937,1.03805020438351,0,1.03841528398748,1.03841528398748
3807626336.92031,,4066.63647460937,1.03797992905202,0,1.03827249965071,1.03827249965071
3807626336.9448,,4066.3779296875,1.03817375456036,0,1.0381310262296,1.0381310262296
3807626336.96929,,4066.80639648438,1.03785257532636,0,1.03799085168851,1.03799085168851
3807626336.99378,,4067.14501953125,1.0375988608147,0,1.03785196410232,1.03785196410232
3807626337.01827,,4067.13647460937,1.03760526184955,0,1.03771435165538,1.03771435165538
3807626337.04275,,4067.15747070313,1.03758953371103,0,1.03757800264051,1.03757800264051
3807626337.06724,,4067.33642578125,1.0374554949606,0,1.03744290545805,1.03744290545805
3807626337.09173,,4067.6025390625,1.03725622765915,0,1.0373090486148,1.0373090486148
3807626337.11622,,4067.81640625,1.03709612901581,0,1.0371764207231,1.0371764207231
3807626337.14071,,4067.67309570313,1.03720340515316,0,1.03704501049983,1.03704501049983
3807626337.16519,,4068.25537109375,1.03676765433318,0,1.03691480676548,1.03691480676548
3807626337.18968,,4068.50146484375,1.03658358010218,0,1.03678579844316,1.03678579844316
3807626337.21417,,4068.41870117188,1.03664547991143,0,1.0366579745577,1.0366579745577
3807626337.23866,,4068.53784179687,1.03655637535885,0,1.03653132423466,1.03653132423466
3807626337.26315,,4068.66186523438,1.03646363260347,0,1.03640583669947,1.03640583669947
3807626337.28763,,4068.88354492188,1.03629789866105,0,1.03628150127647,1.03628150127647
3807626337.31212,,4069.13671875,1.03610867308401,0,1.03615830738801,1.03615830738801
3807626337.33661,,4069.35668945313,1.03594431093312,0,1.03603624455357,1.03603624455357
3807626337.3611,,4069.494140625,1.0358416295503,0,1.03591530238884,1.03591530238884
3807626337.38559,,4069.33569335937,1.03595999733476,0,1.03579547060486,1.03579547060486
3807626337.41007,,4069.37768554687,1.03592862493049,0,1.0356767390071,1.0356767390071
3807626337.43456,,4070.07666015625,1.03540665378461,0,1.03555909749468,1.03555909749468
3807626337.45905,,4070.181640625,1.03532829586085,0,1.03544253605942,1.03544253605942
3807626337.48354,,4069.91650390625,1.03552621429589,0,1.03532704478503,1.03532704478503
3807626337.50803,,4070.03491210937,1.0354378174834,0,1.03521261384628,1.03521261384628
3807626337.53251,,4070.5556640625,1.03504920363695,0,1.03509923350812,1.03509923350812
3807626337.557,,4070.96215820313,1.03474602487743,0,1.0349868941249,1.0349868941249
3807626337.58149,,4070.81372070313,1.03485671797212,0,1.03487558613953,1.03487558613953
3807626337.60598,,4070.97729492188,1.03473473820667,0,1.03476530008264,1.03476530008264
3807626337.63047,,4071.03784179687,1.03468959358877,0,1.03465602657182,1.03465602657182
3807626337.65495,,4071.166015625,1.03459403621683,0,1.03454775631079,1.03454775631079
3807626337.67944,,4071.25854492188,1.03452506207313,0,1.03444048008863,1.03444048008863
3807626337.70393,,4071.86547851562,1.03407282604294,0,1.03433418877899,1.03433418877899
3807626337.72842,,4071.89233398438,1.03405282324207,0,1.03422887333928,1.03422887333928
3807626337.75291,,4071.78198242188,1.03413502071044,0,1.03412452480997,1.03412452480997
3807626337.77739,,4071.80395507812,1.03411865308625,0,1.03402113431375,1.03402113431375
3807626337.80188,,4072.17724609375,1.03384065154758,0,1.03391869305486,1.03391869305486
3807626337.82637,,4071.77685546875,1.03413883988554,0,1.03381719231825,1.03381719231825
3807626337.85086,,4072.50903320313,1.03359366419336,0,1.0337166234689,1.0337166234689
3807626337.87535,,4072.4482421875,1.03363891056129,0,1.03361697795108,1.03361697795108
3807626337.89983,,4072.48461914063,1.03361183502691,0,1.03351824728759,1.03351824728759
3807626337.92432,,4073.029296875,1.03320657069543,0,1.03342042307908,1.03342042307908
3807626337.94881,,4072.80346679687,1.03337456600773,0,1.03332349700331,1.03332349700331
3807626337.9733,,4073.05908203125,1.03318441688533,0,1.03322746081444,1.03322746081444
3807626337.99779,,4073.41479492188,1.03291990366802,0,1.03313230634233,1.03313230634233
3807626338.02227,,4072.79077148438,1.03338401142464,0,1.03303802549187,1.03303802549187
3807626338.04676,,4073.20971679687,1.03307238888163,0,1.03294461024226,1.03294461024226
3807626338.07125,,4073.3955078125,1.03293424293452,0,1.03285205264634,1.03285205264634
3807626338.09574,,4073.39624023438,1.0329336983992,0,1.03276034482992,1.03276034482992
3807626338.12023,,4073.76220703125,1.03266167232307,0,1.0326694789911,1.0326694789911
3807626338.14471,,4073.81298828125,1.0326239356748,0,1.0325794473996,1.0325794473996
3807626338.1692,,4073.82788085937,1.032612869114,0,1.03249024239613,1.03249024239613
3807626338.19369,,4073.86474609375,1.0325854756933,0,1.0324018563917,1.0324018563917
3807626338.21818,,4073.94018554687,1.03252942274661,0,1.03231428186702,1.03231428186702
3807626338.24267,,4074.07177734375,1.03243165971827,0,1.03222751137182,1.03222751137182
3807626338.26715,,4074.4609375,1.03214263287861,0,1.03214153752424,1.03214153752424
3807626338.29164,,4074.36962890625,1.03221043505917,0,1.03205635301017,1.03205635301017
3807626338.31613,,4074.50463867188,1.03211018473689,0,1.03197195058268,1.03197195058268
3807626338.34062,,4074.58642578125,1.03204946235038,0,1.03188832306136,1.03188832306136
3807626338.36511,,4074.80517578125,1.03188708196875,0,1.03180546333173,1.03180546333173
3807626338.38959,,4074.58911132812,1.03204746858163,0,1.03172336434463,1.03172336434463
3807626338.41408,,4075.23510742188,1.03156806370376,0,1.03164201911561,1.03164201911561
3807626338.43857,,4075.25439453125,1.03155375612915,0,1.03156142072436,1.03156142072436
3807626338.46306,,4075.06127929687,1.03169702795098,0,1.03148156231408,1.03148156231408
3807626338.48755,,4075.52661132812,1.03135185548029,0,1.03140243709095,1.03140243709095
3807626338.51203,,4075.1767578125,1.03161135066457,0,1.03132403832351,1.03132403832351
3807626338.53652,,4075.64282226562,1.03126568303164,0,1.03124635934211,1.03124635934211
3807626338.56101,,4075.68212890625,1.03123653919042,0,1.03116939353833,1.03116939353833
3807626338.5855,,4075.8623046875,1.03110296578565,0,1.03109313436441,1.03109313436441
3807626338.60999,,4075.255859375,1.03155266949167,0,1.03101757533274,1.03101757533274
3807626338.63447,,4075.81958007812,1.03113463708028,0,1.03094271001523,1.03094271001523
3807626338.65896,,4075.77587890625,1.03116703397354,0,1.03086853204285,1.03086853204285
3807626338.68345,,4075.783203125,1.03116160420798,0,1.03079503510501,1.03079503510501
3807626338.70794,,4076.66381835937,1.030509113457,0,1.03072221294908,1.03072221294908
3807626338.73243,,4076.18212890625,1.03086593514339,0,1.03065005937981,1.03065005937981
3807626338.75691,,4076.30834960937,1.03077241451924,0,1.03057856825887,1.03057856825887
3807626338.7814,,4076.1005859375,1.03092636026063,0,1.03050773350425,1.03050773350425
3807626338.80589,,4076.71215820313,1.03047331608766,0,1.03043754908979,1.03043754908979
3807626338.83038,,4076.75463867188,1.0304418595063,0,1.03036800904467,1.03036800904467
3807626338.85487,,4076.85180664063,1.03036991313017,0,1.03029910745286,1.03029910745286
3807626338.87935,,4076.65747070313,1.03051381427636,0,1.03023083845269,1.03023083845269
3807626338.90384,,4077.14013671875,1.03015647340173,0,1.03016319623626,1.03016319623626
3807626338.92833,,4076.97729492188,1.03027700987573,0,1.03009617504901,1.03009617504901
3807626338.95282,,4076.97045898438,1.03028207039263,0,1.03002976918923,1.03002976918923
3807626338.97731,,4077.46655273438,1.02991492923986,0,1.02996397300754,1.02996397300754
3807626339.00179,,4077.00048828125,1.03025984057316,0,1.02989878090643,1.02989878090643
3807626339.02628,,4077.58276367188,1.02982895729792,0,1.02983418733978,1.02983418733978
3807626339.05077,,4077.7275390625,1.02972187036341,0,1.0297701868124,1.0297701868124
3807626339.07526,,4077.73681640625,1.02971500876574,0,1.02970677387953,1.02970677387953
3807626555.88869,BEGIN:PULSE:PARAMS
3807626555.88869,ThResSigmaPerCycle=0.55405450015309
3807626555.88869,TempSigmaPerCycle=0.000337341254422419
3807626555.88869,NBinsOn=128
3807626555.88869,NBinsOff=128
3807626555.88869,Period=5.30991815867806
3807626555.88869,Iterations=1
3807626555.88869,HtrOverLoad=0
3807626555.88869,NCycRec=5
3807626555.88869,ThFreqHz=245.017959594727
3807626555.88869,NSampPerBin=5
3807626555.88869,PPMSTemp=0.895126581192017
3807626555.88869,EstTau=2.65495907933903
3807626555.88869,ThermOverload=0
3807626555.88869,ThResCorrFact=1
3807626555.88869,AvgHtrOnResistance=1756.60010831803
3807626555.88869,IsAddenda=0
3807626555.88869,AddendafromTbl=3.56700139452349E-7
3807626555.88869,AddendafromTblMinMidMax=3.55759970752648E-7|3.56513996513052E-7|3.57223573193908E-7
3807626555.88869,AddendaOffsetMinMidMax=0|0|0
3807626555.88869,AddendaErrfromTbl=3.92466451701556E-9
3807626555.88869,CondfromTbl=1.42570359848556E-7
3807626555.88869,TempMinMidMax=0.914795400042705|0.923371826309477|0.931948252576249
3807626555.88869,CondfromTblMinMidMax=1.42603643040853E-7|1.44532126500613E-7|1.46463745963635E-7
3807626555.88869,DisableTau2Fitting=0
3807626555.88869,HtrCurrOn=1.51285458515677E-6
3807626555.88869,StableStartTemperature=0.91472760642434
3807626555.88869,TimeStamp=3807626555.88869
3807626555.88869,PPMSStatus=833
3807626555.88869,PuckTemp=0.895473
3807626555.88869,SystemTemp=0.895473
3807626555.88869,Field=-0.024003511
3807626555.88869,Pressure=9.8999999E-6
3807626555.88869,SampleTemp=0.92252325
3807626555.88869,TempRise=0.014994759
3807626555.88869,SampHC=0.08851471
3807626555.88869,SampHCErr=0.004261
3807626555.88869,AddendaHC=0.35670014
3807626555.88869,AddendaHCErr=0.003925
3807626555.88869,TotalHC=0.44521485
3807626555.88869,TotalHCErr=0.004261
3807626555.88869,FitDeviation=1.0697055
3807626555.88869,TimeConsttau1=3.6222437
3807626555.88869,TimeConsttau2=0.39821081
3807626555.88869,SampleCoupling=57.596137
3807626555.88869,DebyeTemp=
3807626555.88869,DebyeTempErr=
3807626555.88869,CalCorrection=1
3807626555.88869,ThermCondWire=1.269463E-7
3807626555.88869,AddendaOffset=0
3807626555.88869,END:PULSE:PARAMS
3807626555.9091,,4248.96240234375,0.914795400042705,4.03313123231703E-9,0.915140230267332,0.915030355610131
3807626555.9295,,4248.43603515625,0.915116072869217,4.03328587310283E-9,0.915366403037277,0.915043481258781
3807626555.94991,,4247.81591796875,0.915494096740343,4.03299948823072E-9,0.915588863211919,0.915064764779901
3807626555.97032,,4247.36279296875,0.915770484136589,4.03277369154804E-9,0.915807753637471,0.915093749133801
3807626555.99072,,4246.54736328125,0.91626820736808,4.03240206050243E-9,0.916023210263679,0.915130000390357
3807626556.01113,,4246.6552734375,0.916202315519064,4.03204698553185E-9,0.916235362486993,0.915173106573003
3807626556.03154,,4246.24853515625,0.916450717689463,4.03168310413838E-9,0.916444333476598,0.915222676560493
3807626556.05194,,4245.82275390625,0.916710868136637,4.0317690548257E-9,0.916650240484169,0.915278339043529
3807626556.07235,,4245.37890625,0.916982186082397,4.03137311805295E-9,0.916853195138155,0.915339741533517
3807626556.09276,,4245.11376953125,0.917144323358071,4.03085706167209E-9,0.917053303723372,0.915406549420851
3807626556.11316,,4245.015625,0.917204352950648,4.03079858702415E-9,0.917250667446639,0.915478445080254
3807626556.13357,,4244.74755859375,0.917368347224423,4.0306196405112E-9,0.917445382689145,0.915555127020811
3807626556.15398,,4244.48828125,0.917527010401571,4.03031176796726E-9,0.917637541246227,0.915636309078477
3807626556.17438,,4243.9658203125,0.917846863933694,4.03002291729674E-9,0.917827230555162,0.915721719648931
3807626556.19479,,4243.662109375,0.918032881550029,4.0298443230407E-9,0.918014533911598,0.915811100958758
3807626556.2152,,4243.13916015625,0.918353323692282,4.02947128296744E-9,0.918199530675183,0.915904208373051
3807626556.2356,,4242.77734375,0.918575137539671,4.02923879340336E-9,0.918382296464916,0.916000809737609
3807626556.25601,,4242.9384765625,0.918476343194677,4.02913170730112E-9,0.918562903344757,0.916100684754
3807626556.27642,,4242.443359375,0.918779966776663,4.02890450159078E-9,0.918741419999972,0.916203624385858
3807626556.29682,,4242.62255859375,0.918670056398105,4.02849623582599E-9,0.918917911904667,0.916309430294842
3807626556.31723,,4241.6650390625,0.919257593498378,4.02839689937588E-9,0.919092441480968,0.91641791430478
3807626556.33764,,4241.4072265625,0.919415893374481,4.02818237491449E-9,0.919265068250255,0.916528897892586
3807626556.35804,,4241.1650390625,0.919564640036974,4.02786287789234E-9,0.919435848976843,0.91664221170463
3807626556.37845,,4240.66455078125,0.919872154856001,4.02786992303065E-9,0.919604837804499,0.916757695097256
3807626556.39886,,4240.560546875,0.919936079093583,4.02763778572349E-9,0.919772086386143,0.916875195700278
3807626556.41926,,4240.6689453125,0.919869453992228,4.02748173591003E-9,0.919937644007072,0.916994569002283
3807626556.43967,,4240.0830078125,0.920229683887495,4.02688289915408E-9,0.920101557702044,0.917115677956652
3807626556.46008,,4239.75048828125,0.920434217222522,4.0267747562811E-9,0.920263872366517,0.917238392607284
3807626556.48048,,4239.7275390625,0.920448336075369,4.02669972555814E-9,0.920424630862329,0.917362589733008
3807626556.50089,,4239.47705078125,0.920602464938993,4.02631294746518E-9,0.920583874118119,0.917488152509785
3807626556.5213,,4239.4228515625,0.920635820026157,4.02600260912284E-9,0.92074164122473,0.917614970189772
3807626556.5417,,4239.11767578125,0.92082366718571,4.02590503395731E-9,0.920897969525853,0.917742937796442
3807626556.56211,,4238.890625,0.920963466233079,4.02564506835385E-9,0.92105289470415,0.917871955834936
3807626556.58252,,4238.48681640625,0.921212184051189,4.02566549925493E-9,0.921206450863086,0.918001930016888
3807626556.60292,,4238.279296875,0.921340044377724,4.02531746942265E-9,0.921358670604672,0.918132770999012
3807626556.62333,,4238.0986328125,0.921451381756975,4.02525476769173E-9,0.921509585103332,0.918264394134748
3807626556.64374,,4238.033203125,0.921491709381762,4.02495570157067E-9,0.921659224176098,0.918396719238327
3807626556.66414,,4237.52587890625,0.921804497130976,4.02473589325555E-9,0.921807616349283,0.918529670360625
3807626556.68455,,4237.45849609375,0.921846054694589,4.02442238460097E-9,0.921954788921851,0.918663175576228
3807626556.70496,,4237.22119140625,0.921992434039541,4.0242663347875E-9,0.922100768025615,0.918797166781133
3807626556.72536,,4236.73681640625,0.922291334806001,4.02414586292248E-9,0.922245578682438,0.918931579500569
3807626556.74577,,4236.8779296875,0.922204239464766,4.02388977214509E-9,0.922389244858584,0.919066352706423
3807626556.76618,,4236.77978515625,0.922264812998097,4.02372879073481E-9,0.922531789516357,0.919201428643791
3807626556.78658,,4235.86572265625,0.922829273749841,4.02353610620216E-9,0.922673234663167,0.91933675266621
3807626556.80699,,4236.2060546875,0.922619042487247,4.02355407130484E-9,0.922813601398153,0.919472273079113
3807626556.8274,,4235.85986328125,0.922832893913577,4.02328389025083E-9,0.922952909956486,0.919607940991125
3807626556.8478,,4235.18212890625,0.923251783214716,4.02320815501405E-9,0.923091179751453,0.919743710172791
3807626556.86821,,4235.3515625,0.923147031692118,4.02309648957191E-9,0.923228429414458,0.919879536922359
3807626556.88862,,4235.2783203125,0.923192310941029,4.02268787155021E-9,0.923364676833026,0.920015379938291
3807626556.90902,,4234.59521484375,0.923614790655201,4.02233843269027E-9,0.923499939186909,0.920151200198133
3807626556.92943,,4233.9755859375,0.923998286047931,4.02223381238643E-9,0.923634232982404,0.920286960843458
3807626556.94984,,4234.41015625,0.923729298221341,4.02202703757717E-9,0.923767574084954,0.920422627070551
3807626556.97024,,4234.01708984375,0.923972590658598,4.02190797473981E-9,0.923899977750132,0.920558166026567
3807626556.99065,,4234.24951171875,0.923828718102936,4.02177482162584E-9,0.924031458653079,0.920693546710886
3807626557.01106,,4233.8681640625,0.924064797196598,4.02158354612086E-9,0.924162030916482,0.920828739881397
3807626557.03146,,4233.56494140625,0.924252582340052,4.02131442183759E-9,0.924291708137148,0.920963717965474
3807626557.05187,,4233.33056640625,0.924397773103684,4.02135317009827E-9,0.924420503411282,0.921098454975405
3807626557.07228,,4233.25439453125,0.92444496814442,4.02092376891857E-9,0.924548429358471,0.921232926428047
3807626557.09268,,4232.96142578125,0.924626524310783,4.02088748645629E-9,0.924675498144515,0.921367109268514
3807626557.11309,,4232.87353515625,0.924681002547037,4.02069938126354E-9,0.924801721503086,0.921500981797669
3807626557.1335,,4232.64794921875,0.92482085408158,4.02058947710598E-9,0.924927110756341,0.921634523603256
3807626557.1539,,4232.873046875,0.924681305218592,4.02021784606038E-9,0.925051676834494,0.921767715494468
3807626557.17431,,4232.38671875,0.924982846651008,4.02019882418695E-9,0.925175430294418,0.921900539439805
3807626557.19472,,4231.794921875,0.925349999844931,4.0201192141241E-9,0.925298381337329,0.922032978508025
3807626557.21512,,4231.79931640625,0.925347272580461,4.01977365009023E-9,0.925420539825583,0.922165016812064
3807626557.23553,,4231.47021484375,0.925551550800135,4.01969263099972E-9,0.925541915298651,0.922296639455761
3807626557.25594,,4231.00048828125,0.925843244963009,4.01957427267619E-9,0.925662516988289,0.922427832483247
3807626557.27634,,4231.1435546875,0.925754386625034,4.01948585619046E-9,0.925782353832966,0.92255858283087
3807626557.29675,,4230.85009765625,0.925936667417019,4.01924702600191E-9,0.925901434491568,0.922688878281532
3807626557.31716,,4230.5966796875,0.926094125233922,4.01932381800944E-9,0.92601976735643,0.922818707421304
3807626557.33756,,4230.44970703125,0.926185464783316,4.01889688262814E-9,0.926137360565714,0.922948059598229
3807626557.35797,,4230.46630859375,0.926175146620362,4.01894831213777E-9,0.926254222015189,0.923076924883172
3807626557.37838,,4229.97412109375,0.926481129729024,4.01868271042366E-9,0.926370359369407,0.923205294032642
3807626557.39878,,4230.2724609375,0.926295638076819,4.01867002917471E-9,0.926485780072339,0.923333158453481
3807626557.41919,,4229.4208984375,0.926825254736233,4.01813953026032E-9,0.926600491357486,0.923460510169308
3807626557.4396,,4229.4873046875,0.926783936537958,4.01815996116141E-9,0.926714500257486,0.923587341788662
3807626557.46,,4229.2421875,0.926936464274885,4.01821244744178E-9,0.926827813613241,0.923713646474733
3807626557.48041,,4229.423828125,0.926823431810996,4.01783130545947E-9,0.926940438082605,0.92383941791661
3807626557.50082,,4229.21533203125,0.926953177978323,4.01775768376418E-9,0.927052380148632,0.923964650301977
3807626557.52122,,4228.93115234375,0.927130069578567,4.01767913047207E-9,0.927163646127427,0.924089338291175
3807626557.54163,,4228.62060546875,0.927323436982178,4.01737583726803E-9,0.927274242175597,0.924213476992565
3807626557.56204,,4228.724609375,0.927258669793911,4.01739943848135E-9,0.927384174297349,0.924337061939131
3807626557.58244,,4228.23876953125,0.927561284239531,4.01709790656189E-9,0.927493448351229,0.924460089066254
3807626557.60285,,4227.732421875,0.927876844387441,4.01699399077189E-9,0.927602070056531,0.924582554690603
3807626557.62326,,4227.5341796875,0.928000438452414,4.01691790327819E-9,0.927710044999389,0.924704455490087
3807626557.64366,,4228.10205078125,0.927646471213444,4.01681363523127E-9,0.927817378638581,0.924825788484813
3807626557.66407,,4227.71826171875,0.927885671641675,4.01679884044083E-9,0.92792407631103,0.924946551019002
3807626557.68448,,4227.8583984375,0.927798318312304,4.01643953838726E-9,0.928030143237046,0.925066740743815
3807626557.70488,,4227.1513671875,0.928239179098952,4.01653852258045E-9,0.928135584525309,0.925186355601036
3807626557.72529,,4226.93994140625,0.928371077664806,4.01625425124983E-9,0.928240405177613,0.925305393807585
3807626557.7457,,4226.77734375,0.928472535528804,4.01595905995484E-9,0.92834461009336,0.925423853840804
3807626557.7661,,4226.78955078125,0.928464917942181,4.01601260300596E-9,0.928448204073861,0.925541734424484
3807626557.78651,,4226.76318359375,0.928481372057382,4.01605698737728E-9,0.9285511918264,0.925659034515599
3807626557.80692,,4226.4296875,0.928689527327,4.01591256204203E-9,0.928653577968121,0.925775753291703
3807626557.82732,,4226.15966796875,0.928858118936985,4.01547541121018E-9,0.92875536702971,0.925891890138964
3807626557.84773,,4225.58056640625,0.929219860422228,4.01523235393865E-9,0.928856563458905,0.926007444640805
3807626557.86814,,4225.75732421875,0.929109422484129,4.01496499093997E-9,0.928957171623838,0.926122416567111
[...]
3807675632.94748,,11385.4609375,0.104729688332526,1.58865227621322E-11,0.10473643740211,0.103728917748212
3807675640.90199,,11381.3359375,0.104800086813989,1.58850650579353E-11,0.104754730547504,0.103753061180448
3807675648.85651,,11382.1494140625,0.10478619756133,1.58841823777558E-11,0.104772917471499,0.103777064420874
3807675656.81103,,11378.546875,0.104847730327221,1.58781079998398E-11,0.104790998790882,0.103800928283531
3807675664.76555,,11379.2841796875,0.104835131993739,1.5883026835861E-11,0.10480897511886,0.103824653577734
3807675672.72007,,11381.791015625,0.104792316459209,1.5889381400639E-11,0.104826847065076,0.103848241108096
3807675680.67459,,11380.8671875,0.10480809161337,1.58894747962596E-11,0.104844615235638,0.103871691674561
3807675688.62911,,11378.6142578125,0.104846578851958,1.58856309255193E-11,0.104862280233132,0.103895006072426
3807675696.58363,,11374.6083984375,0.104915069733442,1.58833619613233E-11,0.104879842656644,0.103918185092371
3807675704.53815,,11373.970703125,0.104925979697866,1.58750955332519E-11,0.104897303101783,0.103941229520485
3807675712.49267,,11370.2998046875,0.104988819670002,1.58705319668466E-11,0.104914662160698,0.103964140138291
3807675720.44718,,11368.5205078125,0.105019300919958,1.58658878238273E-11,0.104931920422102,0.103986917722776
3807675728.4017,,11370.8359375,0.104979638026022,1.58704019454923E-11,0.104949078471288,0.104009563046414
3807675736.35622,,11368.6611328125,0.105016891328843,1.58673711660377E-11,0.10496613689015,0.104032076877194
3807675744.31074,,11369.134765625,0.105008776367809,1.58667778291535E-11,0.104983096257203,0.104054459978645
3807675752.26526,,11373.6904296875,0.104930775332016,1.58716105947008E-11,0.104999957147606,0.104076713109864
3807675760.21978,,11366.1572265625,0.105059809187447,1.58686512354267E-11,0.105016720133173,0.104098837025538
3807675768.1743,,11364.94140625,0.105080659301388,1.5867552463419E-11,0.105033385782402,0.104120832475973
3807675776.12882,,11363.1123046875,0.105112039539745,1.58639906108273E-11,0.105049954660488,0.104142700207119
3807675784.08334,,11361.767578125,0.105135119731498,1.58619890144866E-11,0.105066427329345,0.104164440960593
3807675792.03785,,11360.474609375,0.105157319524068,1.5860860941892E-11,0.105082804347623,0.104186055473707
3807675799.99237,,11359.07421875,0.105181372502308,1.58552388917858E-11,0.10509908627073,0.104207544479492
3807675807.94689,,11358.2255859375,0.105195952991215,1.58567057524161E-11,0.105115273650846,0.104228908706719
3807675815.90141,,11360.470703125,0.105157386604767,1.58589490785985E-11,0.105131367036949,0.104250148879933
3807675823.85593,,11357.705078125,0.105204897577453,1.58584985820754E-11,0.105147366974824,0.104271265719468
3807675831.81045,,11361.755859375,0.105135320903103,1.58625713636506E-11,0.105163274007091,0.104292259941475
3807675839.76497,,11361.5830078125,0.105138288258424,1.58651260085686E-11,0.105179088673219,0.104313132257949
3807675847.71949,,11354.7412109375,0.105255853805825,1.585678632903E-11,0.105194811509541,0.104333883376749
3807675855.67401,,11357.466796875,0.105208992706797,1.58591761581468E-11,0.10521044304928,0.104354514001625
3807675863.62853,,11360.5048828125,0.105156799651346,1.58636921110985E-11,0.10522598382256,0.104375024832238
3807675871.58304,,11360.197265625,0.105162082428164,1.58646224047317E-11,0.105241434356427,0.10439541656419
3807675879.53756,,11354.73828125,0.105255904194723,1.58551949409055E-11,0.105256795174869,0.104415689889042
3807675887.49208,,11350.8427734375,0.105322940137195,1.58505709420397E-11,0.105272066798828,0.104435845494338
3807675895.4466,,11351.048828125,0.105319392461635,1.58493513051111E-11,0.105287249746224,0.104455884063631
3807675903.40112,,11350.58203125,0.105327429660817,1.58523070018119E-11,0.105302344531967,0.104475806276507
3807675911.35564,,11354.2412109375,0.105264454091636,1.58572240065464E-11,0.10531735166798,0.104495612808602
3807675919.31016,,11352.38671875,0.105296362624573,1.58562552558929E-11,0.10533227166321,0.104515304331631
3807675927.26468,,11350.8173828125,0.105323377305273,1.58545997727346E-11,0.105347105023653,0.104534881513409
3807675935.2192,,11347.7060546875,0.105376970064255,1.58492817162173E-11,0.105361852252363,0.104554345017872
3807675943.17371,,11344.158203125,0.105438137336197,1.58493897621314E-11,0.105376513849475,0.104573695505101
3807675951.12823,,11348.322265625,0.105366352202946,1.58600826450532E-11,0.105391090312219,0.104592933631346
3807675959.08275,,11349.4990234375,0.105346080565072,1.58569987582848E-11,0.105405582134939,0.104612060049043
3807675967.03727,,11342.0419921875,0.105474650322432,1.58452400665156E-11,0.105419989809107,0.104631075406842
3807675974.99179,,11346.755859375,0.105393346261411,1.58505416414528E-11,0.105434313823342,0.104649980349627
3807675982.94631,,11345.189453125,0.105420351826343,1.58512686622646E-11,0.105448554663426,0.104668775518535
3807675990.90083,,11342.66796875,0.105463847566594,1.58424180537424E-11,0.105462712812319,0.104687461550982
3807675998.85535,,11343.169921875,0.105455186468277,1.58436962918447E-11,0.105476788750179,0.104706039080683
3807676006.80987,,11339.482421875,0.105518841128052,1.58464633660175E-11,0.105490782954374,0.104724508737671
3807676014.76439,,11339.171875,0.105524204794346,1.58422330937878E-11,0.1055046958995,0.104742871148323
3807676022.7189,,11342.9033203125,0.105459786476226,1.58448152080059E-11,0.105518528057399,0.104761126935379
3807676030.67342,,11343.09765625,0.105456433323874,1.58412808247144E-11,0.10553227989717,0.104779276717961
3807676038.62794,,11339.0634765625,0.105526077124306,1.58395850532492E-11,0.105545951885192,0.104797321111597
3807676046.58246,,11334.6298828125,0.105602704511094,1.58334410864394E-11,0.105559544485134,0.104815260728241
3807676054.53698,,11333.158203125,0.105628160553546,1.58324869860793E-11,0.105573058157971,0.104833096176293
3807676062.4915,,11335.9091796875,0.105580584461834,1.58361660410185E-11,0.105586493362004,0.104850828060622
3807676070.44602,,11336.197265625,0.105575604293247,1.58385430511285E-11,0.105599850552871,0.104868456982583
3807676078.40054,,11333.3095703125,0.105625541843011,1.58367721969094E-11,0.105613130183566,0.104885983540039
3807676086.35506,,11328.8388671875,0.105702932298667,1.58307637453139E-11,0.105626332704452,0.104903408327383
3807676094.30957,,11330.966796875,0.105666084836623,1.58264895222039E-11,0.105639458563276,0.104920731935555
3807676102.26409,,11334.1044921875,0.105611791162921,1.58342633341585E-11,0.105652508205185,0.104937954952064
3807676110.21861,,11334.16796875,0.105610693264108,1.58332048504577E-11,0.105665482072743,0.104955077961009
3807676118.17313,,11328.97265625,0.105700614962484,1.58276963401257E-11,0.105678380605942,0.104972101543096
3807676126.12765,,11331.41015625,0.105658410269456,1.58299524853149E-11,0.105691204242221,0.104989026275658
3807676134.08217,,11329.25390625,0.105695743757792,1.58305018713187E-11,0.105703953416479,0.105005852732678
3807676142.03669,,11331.009765625,0.10566534100535,1.5833243307478E-11,0.105716628561087,0.105022581484806
3807676149.99121,,11332.9794921875,0.105631252460628,1.58363198690996E-11,0.105729230105909,0.105039213099375
3807676157.94573,,11327.080078125,0.105733403833906,1.58291503817492E-11,0.105741758478309,0.105055748140428
3807676165.90025,,11321.64453125,0.105827668799265,1.5820431625868E-11,0.105754214103175,0.105072187168731
3807676173.85476,,11323.52734375,0.105795000633079,1.58220303391392E-11,0.105766597402921,0.105088530741793
3807676181.80928,,11323.98828125,0.105787005591446,1.58198364576971E-11,0.105778908797514,0.105104779413887
3807676189.7638,,11325.162109375,0.105766649880562,1.5818922645644E-11,0.105791148704479,0.105120933736068
3807676197.71832,,11324.2861328125,0.105781839839123,1.5822517461396E-11,0.105803317538919,0.105136994256188
3807676205.67284,,11325.0693359375,0.105768258455573,1.58275956193583E-11,0.105815415713524,0.105152961518923
3807676213.62736,,11320.84765625,0.105841500220893,1.582261451959E-11,0.105827443638589,0.105168836065782
3807676221.58188,,11320.2236328125,0.105852333546846,1.58211678031132E-11,0.105839401722028,0.105184618435131
3807676229.5364,,11320.41796875,0.105848959590024,1.5820014092505E-11,0.105851290369384,0.10520030916221
3807676237.49092,,11318.1357421875,0.105888593694437,1.58182707075861E-11,0.105863109983846,0.105215908779152
3807676245.44543,,11318.2880859375,0.105885947258915,1.58161445837512E-11,0.105874860966262,0.105231417814999
3807676253.39995,,11361.0126953125,0.105148079842074,0,0.105249733039889,0.105231802277139
3807676261.35447,,11388.5693359375,0.104676691334666,0,0.104691870867597,0.105219083143528
3807676269.30899,,11398.1044921875,0.104514397978206,0,0.104546241479873,0.105203244437449
3807676277.26351,,11400.095703125,0.104480559222724,0,0.104501148945232,0.105186719309989
3807676285.21803,,11400.708984375,0.104470140746283,0,0.104480617759798,0.105170100406723
3807676293.17255,,11403.931640625,0.104415422286536,0,0.104466128742771,0.105153531756664
3807676301.12707,,11405.8427734375,0.104382995033237,0,0.104453167564052,0.105137048042031
3807676309.08159,,11400.833984375,0.104468017446647,0,0.104440633546095,0.105120657294473
3807676317.0361,,11398.90625,0.104500770672455,0,0.104428258083307,0.105104361052076
3807676324.99062,,11403.2919921875,0.104426279289576,0,0.104415975387591,0.105088159272571
3807676332.94514,,11405.69921875,0.10438543022524,0,0.104403769108997,0.105072051530901
3807676340.89966,,11407.6953125,0.104351577911711,0,0.104391634949834,0.105056037311116
3807676348.85418,,11406.3369140625,0.104374613392018,0,0.104379571551935,0.105040116077505
3807676356.8087,,11408.599609375,0.10433624767947,0,0.104367578275442,0.105024287291919
3807676364.76322,,11406.8154296875,0.104366497846673,0,0.104355654657374,0.105008550417984
3807676372.71774,,11410.7802734375,0.104299294993313,0,0.104343800279646,0.10499290492211
3807676380.67226,,11411.7109375,0.104283530928225,0,0.104332014736889,0.104977350273724
3807676388.62678,,11414.5166015625,0.104236031049282,0,0.104320297628597,0.104961885945317
3807676396.58129,,11414.9873046875,0.104228065561293,0,0.1043086485572,0.104946511412434
3807676404.53581,,11414.5703125,0.104235122073286,0,0.104297067127584,0.104931226153668
3807676412.49033,,11415.22265625,0.104224083195681,0,0.104285552946969,0.104916029650638
3807676420.44485,,11415.892578125,0.104212748880116,0,0.10427410562486,0.104900921387973
3807676428.39937,,11409.0732421875,0.104328219836416,0,0.104262724773037,0.104885900853294
3807676436.35389,,11416.111328125,0.104209048321643,0,0.10425141000553,0.104870967537197
3807676444.30841,,11415.19140625,0.104224611959987,0,0.104240160938613,0.104856120933239
3807676452.26293,,11411.0146484375,0.104295324657177,0,0.104228977190787,0.104841360537912
3807676460.21745,,11410.953125,0.104296366846173,0,0.104217858382768,0.104826685850638
3807676468.17196,,11416.611328125,0.104200590720173,0,0.104206804137477,0.104812096373741
3807676476.12648,,11411.033203125,0.104295010349616,0,0.104195814080021,0.104797591612436
3807676484.081,,11409.0029296875,0.104329411533945,0,0.104184887837686,0.104783171074813
3807676492.03552,,11415.4833984375,0.104219671491794,0,0.104174025039922,0.104768834271816
3807676499.99004,,11414.654296875,0.104233700791756,0,0.104163225318329,0.10475458071723
3807676507.94456,,11420.3974609375,0.104136584424735,0,0.104152488306649,0.104740409927662
3807676515.89908,,11420.478515625,0.104135214870883,0,0.104141813640748,0.104726321422527
3807676523.8536,,11418.212890625,0.104173507623124,0,0.104131200958609,0.104712314724031
3807676531.80812,,11414.73828125,0.104232279542273,0,0.104120649900313,0.104698389357154
3807676539.76264,,11419.3916015625,0.104153582576795,0,0.104110160108037,0.104684544849632
3807676547.71715,,11421.7724609375,0.104113355552747,0,0.104099731226029,0.104670780731947
3807676555.67167,,11419.189453125,0.104156999265218,0,0.104089362900609,0.104657096537305
3807676563.62619,,11420.7529296875,0.104130578410232,0,0.104079054780146,0.104643491801623
3807676571.58071,,11419.560546875,0.104150727226089,0,0.104068806515052,0.104629966063513
3807676579.53523,,11423.603515625,0.104082435546258,0,0.104058617757771,0.104616518864265
3807676587.48975,,11427.259765625,0.104020739982986,0,0.104048488162763,0.104603149747834
3807676595.44427,,11426.818359375,0.104028185055842,0,0.104038417386494,0.104589858260823
3807676603.39879,,11427.8173828125,0.104011336075374,0,0.104028405087427,0.104576643952467
3807676611.35331,,11427.8212890625,0.10401127020356,0,0.104018450926007,0.104563506374618
3807676619.30782,,11429.1611328125,0.103988680255104,0,0.104008554564649,0.104550445081732
3807676627.26234,,11424.1064453125,0.104073945514767,0,0.103998715667732,0.104537459630849
3807676635.21686,,11427.3125,0.104019850586419,0,0.10398893390158,0.104524549581585
3807676643.17138,,11433.3779296875,0.103917637495717,0,0.103979208934457,0.104511714496111
3807676651.1259,,11432.6630859375,0.103929675212504,0,0.103969540436552,0.10449895393914
3807676659.08042,,11429.69140625,0.103979742017324,0,0.10395992807997,0.104486267477913
3807676667.03494,,11423.9892578125,0.104075923672016,0,0.103950371538719,0.104473654682184
3807676674.98946,,11428.720703125,0.103996105062912,0,0.103940870488701,0.104461115124205
3807676682.94398,,11433.1875,0.103920844038896,0,0.103931424607699,0.104448648378713
3807676690.8985,,11430.8740234375,0.103959812519807,0,0.103922033575367,0.104436254022913
3807676698.85301,,11428.3427734375,0.104002476939634,0,0.10391269707322,0.104423931636464
3807676706.80753,,11433.6826171875,0.103912507367511,0,0.103903414784622,0.104411680801469
3807676714.76205,,11434.578125,0.103897431822184,0,0.103894186394774,0.104399501102454
3807676722.71657,,11437.46484375,0.103848859619401,0,0.103885011590708,0.104387392126361
3807676730.67109,,11432.919921875,0.103925349920052,0,0.10387589006127,0.104375353462527
3807676738.62561,,11438.0341796875,0.103839284358329,0,0.103866821497115,0.104363384702676
3807676746.58013,,11443.2705078125,0.103751286736315,0,0.103857805590694,0.104351485440902
3807676754.53465,,11441.955078125,0.103773381201115,0,0.103848842036243,0.104339655273655
3807676762.48917,,11443.0185546875,0.103755518035326,0,0.103839930529774,0.10432789379973
3807676770.44368,,11445.0146484375,0.103722003482011,0,0.103831070769063,0.104316200620251
3807676778.3982,,11443.5478515625,0.103746629357616,0,0.103822262453644,0.104304575338657
3807676786.35272,,11444.9423828125,0.103723216514258,0,0.103813505284791,0.104293017560691
3807676794.30724,,11444.1787109375,0.103736036749801,0,0.103804798965517,0.104281526894385
3807676802.26176,,11436.4892578125,0.103865270713336,0,0.103796143200558,0.104270102950047
3807676810.21628,,11437.6220703125,0.10384621519021,0,0.103787537696362,0.104258745340247
3807676818.1708,,11438.3671875,0.103833684411428,0,0.103778982161086,0.104247453679807
3807676826.12532,,11438.0263671875,0.103839415741352,0,0.103770476304578,0.104236227585781
3807676834.07984,,11441.34765625,0.103783586322293,0,0.103762019838372,0.104225066677453
3807676842.03435,,11442.0380859375,0.103771986739594,0,0.103753612475678,0.104213970576311
3807676849.98887,,11445.4736328125,0.10371429963616,0,0.103745253931369,0.104202938906047
3807676857.94339,,11444.431640625,0.103731790371096,0,0.103736943921977,0.104191971292533
3807676865.89791,,11445.2529296875,0.103718003920401,0,0.103728682165677,0.104181067363816
3807676873.85243,,11446.5849609375,0.103695650416667,0,0.103720468382281,0.104170226750103
3807676881.80695,,11445.6474609375,0.103711382256712,0,0.10371230229323,0.104159449083748
3807676889.76147,,11447.794921875,0.103675352347878,0,0.103704183621579,0.104148733999238
3807676897.71599,,11444.4189453125,0.103732003502919,0,0.103696112091994,0.104138081133186
3807676905.67051,,11449.84375,0.103640996597141,0,0.103688087430739,0.10412749012431
3807676913.62503,,11449.8857421875,0.103640292648666,0,0.103680109365667,0.104116960613431
3807676921.57954,,11451.3056640625,0.103616494023605,0,0.103672177626211,0.104106492243453
3807676929.53406,,11449.4052734375,0.103648347601637,0,0.103664291943377,0.104096084659352
3807676937.48858,,11451.2607421875,0.103617246798962,0,0.10365645204973,0.10408573750817
3807676945.4431,,11452.017578125,0.103604565378877,0,0.10364865767939,0.104075450438994
3807676953.39762,,11452.7548828125,0.103592213690478,0,0.103640908568021,0.104065223102951
3807676961.35214,,11449.6884765625,0.103643599638147,0,0.10363320445282,0.104055055153193
3807676969.30666,,11451.1123046875,0.103619734294891,0,0.103625545072512,0.104044946244886
3807676977.26118,,11451.419921875,0.103614579396686,0,0.103617930167339,0.1040348960352
3807676985.2157,,11452.4365234375,0.103597546703377,0,0.103610359479049,0.104024904183293
3807676993.17021,,11453.6826171875,0.103576675292098,0,0.103602832750893,0.104014970350303
3807677001.12473,,11451.1240234375,0.103619537910024,0,0.103595349727609,0.104005094199337
3807677009.07925,,11453.669921875,0.103576887896774,0,0.103587910155421,0.103995275395456
3807677017.03377,,11458.5234375,0.103495660076899,0,0.103580513782025,0.103985513605669
3807677024.98829,,11455.623046875,0.103544187969149,0,0.10357316035658,0.103975808498915
3807677032.94281,,11452.4150390625,0.103597906616295,0,0.103565849629705,0.103966159746057
3807677040.89733,,11451.7392578125,0.103609228570275,0,0.103558581353466,0.10395656701987
3807677048.85185,,11455.2373046875,0.10355064485129,0,0.103551355281366,0.103947029995029
3807677056.80637,,11457.0888671875,0.103519657890113,0,0.103544171168344,0.103937548348095
3807677064.76089,,11452.95703125,0.103588827626649,0,0.103537028770758,0.103928121757511
3807677072.7154,,11456.7841796875,0.103524755955843,0,0.103529927846382,0.103918749903585
3807677080.66992,,11459.791015625,0.103474463402656,0,0.103522868154397,0.103909432468482
3807677088.62444,,11459.8193359375,0.103473989907196,0,0.103515849455383,0.103900169136213
3807677096.57896,,11462.326171875,0.103432091587593,0,0.103508871511308,0.103890959592622
3807677104.53348,,11462.5888671875,0.103427702620367,0,0.103501934085523,0.103881803525379
3807677112.488,,11461.4638671875,0.103446500659927,0,0.103495036942756,0.103872700623968
3807677120.44252,,11462.2294921875,0.103433706935606,0,0.103488179849096,0.103863650579673
3807677128.39704,,11461.4140625,0.103447332995403,0,0.103481362571994,0.103854653085574
3807677136.35156,,11460.0986328125,0.103469320454194,0,0.103474584880251,0.103845707836532
3807677144.30607,,11458.7470703125,0.103491919926197,0,0.103467846544009,0.103836814529179
3807677152.26059,,11457.564453125,0.103511701162307,0,0.103461147334745,0.10382797286191
3807677160.21511,,11460.9951171875,0.103454334844038,0,0.103454487025265,0.103819182534869
3807677168.16963,,11458.3583984375,0.10349842041882,0,0.10344786538969,0.103810443249944
3807677176.12415,,11456.5732421875,0.103528285629248,0,0.103441282203458,0.103801754710752
3807677184.07867,,11455.5322265625,0.103545708137192,0,0.103434737243306,0.103793116622632
3807677192.03319,,11458.056640625,0.103503467749434,0,0.103428230287271,0.103784528692634
3807677199.98771,,11465.158203125,0.103384791815374,0,0.103421761114677,0.103775990629508
3807677207.94223,,11466.748046875,0.103358254374375,0,0.103415329506129,0.103767502143696
3807677215.89674,,11463.86328125,0.103406414789308,0,0.103408935243508,0.103759062947322
3807677223.85126,,11465.017578125,0.103387139649746,0,0.10340257810996,0.103750672754179
3807677231.80578,,11466.041015625,0.103370054646549,0,0.103396257889889,0.103742331279725
3807677239.7603,,11464.904296875,0.103389031024888,0,0.103389974368955,0.10373403824107
3807677247.71482,,11459.1533203125,0.103485126163198,0,0.103383727334057,0.103725793356963
3807677255.66934,,11458.6533203125,0.10349348782242,0,0.103377516573337,0.103717596347791
3807677263.62386,,11460.5595703125,0.103461614986242,0,0.103371341876163,0.103709446935561